Workbook
Name _k1: verify!$C$12
Name _k1: formula!$C$14
Name _k2: verify!$C$13
Name _k2: formula!$C$15
Name _k3: verify!$C$14
Name _k3: formula!$C$16
Name _k4: verify!$C$15
Name _k4: formula!$C$17
Name _k5: verify!$C$16
Name _k5: formula!$C$18
Name formulas: parameters!$A$2:$A$5
Name formulas: parameters!$A$2:$A$5
Name table: parameters!$B$2:$F$5
Name table: parameters!$B$2:$F$5

Sheet formula
A1: BREAKWATER ARMOR CALCULATOR
A3: INPUTS & CONTROLS | H3: HEAD ARMOR RESULTS
A4: Formula ID | C4: 1 | E4: Selected Formula | F4: =INDEX(parameters!$A$2:$A$5,$C$4) -> Van der Meer (1988a) - Simple Cubes (Slope 2.0:1) | H4: Kd Ratio | K4: =$F$9 -> 1.5
A5: Block Type | C5: =INDEX(parameters!$G$2:$G$5,$C$4) -> Cubes | E5: Slope Ratio | F5: =INDEX(parameters!$H$2:$H$5,$C$4) -> 2 | H5: Kd Head (eq.) | K5: =$C$28/$K$4 -> 3.400713
A6: Hs [m] | C6: 11 | E6: P_cubes [-] | F6: 0.4 | H6: delta_head [-] | K6: =$F$18*($K$4^(1/3)) -> 1.9853104
A7: Tm [s] | C7: 11.9 | E7: P_rock [-] | F7: 0.25 | H7: Wc Head [kN/m³] | K7: =$C$11*($K$6+1) -> 30.002369
A8: Number of Waves (Nz) | C8: 3000 | E8: g [m/s²] | F8: 9.80665 | H8: Ns_head | K8: =$C$6/($K$6*$C$25) -> 1.8946689
A9: Nod (Damage) | C9: 0.5 | E9: KD Ratio Fixed | F9: 1.5 | H9: Dn [m] | K9: =$C$25 -> 2.9243608
A10: Wc Trunk [kN/m³] | C10: 27.48 | E10: W_rock_spec [kN/m³] | F10: 26.5 | H10: Block Weight W [kN] | K10: =$C$26*($K$7/$C$10) -> 750.32324
A11: Ww [kN/m³] | C11: 10.05 | E11: Storm Duration [h] | F11: =($C$8*$C$7)/3600 -> 9.9166667 | H11: Mass [t] | K11: =$K$10/$F$8 -> 76.511677
H12: Packing d [units/100m²] | K12: =100*2*1.1*(1-$F$6)/$K$9^2 -> 15.435192
A13: COEFFICIENTS & HYDRAULICS | H13: Volume [m³] | K13: =$K$10/$K$7 -> 25.0088
A14: k1 | C14: =INDEX(parameters!$B$2:$B$5,$C$4) -> 7.3743042 | E14: L0 [m] | F14: =($F$8*$C$7^2)/(2*PI()) -> 221.02161 | H14: Height H [m] | K14: =($K$13/1.0247)^(1/3) -> 2.9006725
A15: k2 | C15: =INDEX(parameters!$C$2:$C$5,$C$4) -> 0.4 | E15: k0 [1/m] | F15: =(2*PI())/$F$14 -> 0.028427924 | H15: Base Width A [m] | K15: =1.086*$K$14 -> 3.1501304
A16: k3 | C16: =INDEX(parameters!$D$2:$D$5,$C$4) -> 0.3 | E16: s0m [-] | F16: =$C$6/$F$14 -> 0.04976889 | H16: Top Width B [m] | K16: =1.005*$K$14 -> 2.9151759
A17: k4 | C17: =INDEX(parameters!$E$2:$E$5,$C$4) -> 1.1006424 | E17: sm [-] | F17: =$F$16 -> 0.04976889
A18: k5 | C18: =INDEX(parameters!$F$2:$F$5,$C$4) -> 0.1 | E18: delta_trunk [-] | F18: =($C$10/$C$11)-1 -> 1.7343284 | H18: TRUNK UNDERLAYER
A19: term_damage | C19: =$C$9^$C$15 -> 0.75785828 | E19: term_waves | F19: =$C$8^$C$16 -> 11.044254 | H19: Target W/10 [kN] | K19: =$C$26/10 -> 68.724181
A20: damage/wave ratio | C20: =$C$19/$F$19 -> 0.068620144 | E20: scaled_term | F20: =$C$14*$C$20 -> 0.50602582 | H20: Target Mass [kg] | K20: =($K$19*1000)/$F$8 -> 7007.9162
A21: inv_f = scaled + k4 | C21: =$F$20+$C$17 -> 1.6066682 | E21: steepness_factor | F21: =$F$16^(-$C$18) -> 1.3499081 | H21: Adopted Grading | K21: =INDEX(parameters!$J$2:$J$18,parameters!$N$21) -> HMA6000-10000
A22: Ns_trunk | C22: =$C$21*$F$21 -> 2.1688545 | H22: NLL [kg] | K22: =INDEX(parameters!$K$2:$K$18,parameters!$N$21) -> 6000
H23: NUL [kg] | K23: =INDEX(parameters!$L$2:$L$18,parameters!$N$21) -> 10000
A24: TRUNK ARMOR RESULTS | H24: M50 [kg] | K24: =0.5*($K$22+$K$23) -> 8000
A25: Dn [m] | C25: =$C$6/($F$18*$C$22) -> 2.9243608 | H25: ELL [kg] | K25: =0.7*$K$22 -> 4200
A26: Block Weight W [kN] | C26: =$C$10*$C$25^3 -> 687.24181 | H26: EUL [kg] | K26: =1.5*$K$23 -> 15000
A27: Mass [t] | C27: =$C$26/$F$8 -> 70.079162 | H27: W_mean [kN] | K27: =($K$24*$F$8)/1000 -> 78.4532
A28: Kd Trunk (eq.) | C28: =($C$10*$C$6^3)/($C$26*$F$18^3*$F$5) -> 5.1010695 | H28: Dn_rock [m] | K28: =($K$27/$F$10)^(1/3) -> 1.4358914
A29: Double Layer r1 [m] | C29: =2*1.1*$C$25 -> 6.4335937 | H29: r2 [m] | K29: =2*$K$28 -> 2.8717828
A30: Packing d [units/100m²] | C30: =100*2*1.1*(1-$F$6)/$C$25^2 -> 15.435192 | H30: f2 [rocks/100m²] | K30: =100*2*1*(1-$F$7)/$K$28^2 -> 72.752524
A31: Volume [m³] | C31: =$C$26/$C$10 -> 25.0088
A32: Height H [m] | C32: =($C$31/1.0247)^(1/3) -> 2.9006725 | H32: HEAD UNDERLAYER
A33: Base Width A [m] | C33: =1.086*$C$32 -> 3.1501304 | H33: Target W/10 [kN] | K33: =$K$10/10 -> 75.032324
A34: Top Width B [m] | C34: =1.005*$C$32 -> 2.9151759 | H34: Target Mass [kg] | K34: =($K$33*1000)/$F$8 -> 7651.1677
H35: Adopted Grading | K35: =INDEX(parameters!$J$2:$J$18,parameters!$O$21) -> HMA6000-10000
H36: NLL [kg] | K36: =INDEX(parameters!$K$2:$K$18,parameters!$O$21) -> 6000
H37: NUL [kg] | K37: =INDEX(parameters!$L$2:$L$18,parameters!$O$21) -> 10000
H38: M50 [kg] | K38: =0.5*($K$36+$K$37) -> 8000
H39: ELL [kg] | K39: =0.7*$K$36 -> 4200
H40: EUL [kg] | K40: =1.5*$K$37 -> 15000
H41: W_mean [kN] | K41: =($K$38*$F$8)/1000 -> 78.4532
...

Sheet verify
A1: FORMULAS FOR CUBES & ANTIFER CUBES
K6: Ns = Hs/delta/Dn | L6: =C18/C34/F19 -> 2.1688476
K7: 1/f=(k1*Nod^k2/Nz^k3+k4) | L7: =(_k1*C27^_k2/C25^_k3+_k4) -> 1.6066631
K8: f | L8: =1/L7 -> 0.62240801 | M8: =1/(_k1*C27^_k2/C25^_k3+_k4) -> 0.62240801
K9: (1/f-k4)/k1 | L9: =(1/L8-_k4)/_k1 -> 0.068619452
K10: Nod^k2/Nz^k3 | L10: =C27^_k2/C25^_k3 -> 0.068619452
A12: k1 | C12: =INDEX(table,$F$12,1) -> 7.3743042 | E12: Formula: | F12: 1
A13: k2 | C13: =INDEX(table,$F$12,2) -> 0.4 | D13: 1= | E13: =INDEX(formulas,1,1) -> Van Der Meer (1988a) formula for Cubes (not Antifer), slope 2.0:1
A14: k3 | C14: =INDEX(table,$F$12,3) -> 0.3 | D14: 2= | E14: =INDEX(formulas,2,1) -> Van Der Meer (1988a) formula for Cubes (not Antifer), slope 1.5:1
A15: k4 | C15: =INDEX(table,$F$12,4) -> 1.1006424 | D15: 3= | E15: =INDEX(formulas,3,1) -> Chegini-Aghtouman (2006) formula for Antifer Cubes, slope 2:1 | K15: Dn | L15: =(F20/C31)^0.333333333 -> 3.1023597
A16: k5 | C16: =INDEX(table,$F$12,5) -> 0.1 | D16: 4= | E16: =INDEX(formulas,4,1) -> Chegini-Aghtouman (2006) formula for Antifer Cubes, slope 1.5:1 | K16: Hs / delta / Dn | L16: =C18/C34/L15 -> 2.1688476
K17: 1/f *sm^-k5 | L17: =L7*C22^-_k5 -> 2.1688476
A18: Hs [m] | C18: 11 | E18: Hs/(DD50) | F18: =(_k1*C27^_k2/C25^_k3+_k4)/C29^_k5 -> 2.1688476 | K18: Dn | L18: =L8*C18/C34*C22^_k5 -> 3.1023597
A19: Tm [s] | C19: 11.9 | E19: D50 | F19: =C18/C34/F18 -> 3.1023597
A20: L0 [m] | C20: =9.80665*C19^2/(2*PI()) -> 221.02161 | E20: W=Wc.D3 [kN] | F20: =F19^3*C31 -> 790.6685
A21: k0 | C21: =2*PI()/C20 -> 0.028427924 | E21: Kd,Hudson | F21: =IF(F12=3,C35*C18^3/2/F20,C35*C18^3/2/F20) -> 5.1010209
A22: s0m=Hs0/L0 | C22: =C18/C20 -> 0.04976889 | E22: Double layer, r1 [m] | F22: =2*1.1*F19 -> 6.8251914
E23: Porosity, P [%] | F23: 40 | K23: W | L23: =C31*(L8*C18/C34)^3*C22^(3*_k5) -> 790.6685
A24: Duration [h] | C24: 9.917 | E24: f1 [cubes/100m2] | F24: =100*2*1.1*(1-F23/100)/F19^2 -> 13.714805 | L24: =C31*(2*PI()/9.80665)^(3*_k5)/C34^3*L8^3*C18^(3+3*_k5)/C19^(6*_k5) -> 790.6685
A25: Nz [waves] | C25: =C24*3600/C19 -> 3000.1008
A27: Nod (damage) | C27: 0.5
A29: sm=Hs/L0 | C29: =C18/C20 -> 0.04976889
A31: Wc [kN/m3] | C31: 26.48
A33: Ww [kN/m3] | C33: 10.05
A34: D=(Wc/Ww)-1 | C34: =C31/C33-1 -> 1.6348259
A35: Wc/(Wc/Ww-1)3 | C35: =C31/C34^3 -> 6.0604305

Sheet parameters
A1: Formula | B1: k1 | C1: k2 | D1: k3 | E1: k4 | F1: k5 | G1: Type | H1: Slope Ratio | J1: Grading | K1: NLL_kg | L1: NUL_kg | M1: Range_kg | N1: TrunkWidth | O1: HeadWidth
A2: Van der Meer (1988a) - Simple Cubes (Slope 2.0:1) | B2: =6.7*(2/1.5)^(1/3) -> 7.3743042 | C2: 0.4 | D2: 0.3 | E2: =1*(2/1.5)^(1/3) -> 1.1006424 | F2: 0.1 | G2: Cubes | H2: 2 | J2: CP32/90 | K2: 0.868 | L2: 19.319 | M2: =L2-K2 -> 18.451 | N2: =IF(AND(formula!$K$20>$K2,formula!$K$20<$L2),$M2,1E+99) -> 1e+99 | O2: =IF(AND(formula!$K$34>$K2,formula!$K$34<$L2),$M2,1E+99) -> 1e+99
A3: Van der Meer (1988a) - Simple Cubes (Slope 1.5:1) | B3: 6.7 | C3: 0.4 | D3: 0.3 | E3: 1 | F3: 0.1 | G3: Cubes | H3: 1.5 | J3: CP45/125 | K3: 2.415 | L3: 51.758 | M3: =L3-K3 -> 49.343 | N3: =IF(AND(formula!$K$20>$K3,formula!$K$20<$L3),$M3,1E+99) -> 1e+99 | O3: =IF(AND(formula!$K$34>$K3,formula!$K$34<$L3),$M3,1E+99) -> 1e+99
A4: Chegini-Aghtouman (2006) - Antifer (Slope 2:1) | B4: 6.138 | C4: 0.443 | D4: 0.276 | E4: 1.164 | F4: 0.07 | G4: Antifer | H4: 2 | J4: CP63/180 | K4: 6.626 | L4: 154.548 | M4: =L4-K4 -> 147.922 | N4: =IF(AND(formula!$K$20>$K4,formula!$K$20<$L4),$M4,1E+99) -> 1e+99 | O4: =IF(AND(formula!$K$34>$K4,formula!$K$34<$L4),$M4,1E+99) -> 1e+99
A5: Chegini-Aghtouman (2006) - Antifer (Slope 1.5:1) | B5: 6.951 | C5: 0.443 | D5: 0.291 | E5: 1.082 | F5: 0.082 | G5: Antifer | H5: 1.5 | J5: CP90/250 | K5: 19.319 | L5: 414.063 | M5: =L5-K5 -> 394.744 | N5: =IF(AND(formula!$K$20>$K5,formula!$K$20<$L5),$M5,1E+99) -> 1e+99 | O5: =IF(AND(formula!$K$34>$K5,formula!$K$34<$L5),$M5,1E+99) -> 1e+99
J6: CP45/180 | K6: 2.415 | L6: 154.548 | M6: =L6-K6 -> 152.133 | N6: =IF(AND(formula!$K$20>$K6,formula!$K$20<$L6),$M6,1E+99) -> 1e+99 | O6: =IF(AND(formula!$K$34>$K6,formula!$K$34<$L6),$M6,1E+99) -> 1e+99
J7: CP90/180 | K7: 19.319 | L7: 154.548 | M7: =L7-K7 -> 135.229 | N7: =IF(AND(formula!$K$20>$K7,formula!$K$20<$L7),$M7,1E+99) -> 1e+99 | O7: =IF(AND(formula!$K$34>$K7,formula!$K$34<$L7),$M7,1E+99) -> 1e+99
J8: LMA5-40 | K8: 5 | L8: 40 | M8: =L8-K8 -> 35 | N8: =IF(AND(formula!$K$20>$K8,formula!$K$20<$L8),$M8,1E+99) -> 1e+99 | O8: =IF(AND(formula!$K$34>$K8,formula!$K$34<$L8),$M8,1E+99) -> 1e+99
J9: LMA10-60 | K9: 10 | L9: 60 | M9: =L9-K9 -> 50 | N9: =IF(AND(formula!$K$20>$K9,formula!$K$20<$L9),$M9,1E+99) -> 1e+99 | O9: =IF(AND(formula!$K$34>$K9,formula!$K$34<$L9),$M9,1E+99) -> 1e+99
J10: LMA15-120 | K10: 15 | L10: 120 | M10: =L10-K10 -> 105 | N10: =IF(AND(formula!$K$20>$K10,formula!$K$20<$L10),$M10,1E+99) -> 1e+99 | O10: =IF(AND(formula!$K$34>$K10,formula!$K$34<$L10),$M10,1E+99) -> 1e+99
J11: LMA40-200 | K11: 40 | L11: 200 | M11: =L11-K11 -> 160 | N11: =IF(AND(formula!$K$20>$K11,formula!$K$20<$L11),$M11,1E+99) -> 1e+99 | O11: =IF(AND(formula!$K$34>$K11,formula!$K$34<$L11),$M11,1E+99) -> 1e+99
J12: LMA60-300 | K12: 60 | L12: 300 | M12: =L12-K12 -> 240 | N12: =IF(AND(formula!$K$20>$K12,formula!$K$20<$L12),$M12,1E+99) -> 1e+99 | O12: =IF(AND(formula!$K$34>$K12,formula!$K$34<$L12),$M12,1E+99) -> 1e+99
J13: LMA15-300 | K13: 15 | L13: 300 | M13: =L13-K13 -> 285 | N13: =IF(AND(formula!$K$20>$K13,formula!$K$20<$L13),$M13,1E+99) -> 1e+99 | O13: =IF(AND(formula!$K$34>$K13,formula!$K$34<$L13),$M13,1E+99) -> 1e+99
J14: HMA300-1000 | K14: 300 | L14: 1000 | M14: =L14-K14 -> 700 | N14: =IF(AND(formula!$K$20>$K14,formula!$K$20<$L14),$M14,1E+99) -> 1e+99 | O14: =IF(AND(formula!$K$34>$K14,formula!$K$34<$L14),$M14,1E+99) -> 1e+99
J15: HMA1000-3000 | K15: 1000 | L15: 3000 | M15: =L15-K15 -> 2000 | N15: =IF(AND(formula!$K$20>$K15,formula!$K$20<$L15),$M15,1E+99) -> 1e+99 | O15: =IF(AND(formula!$K$34>$K15,formula!$K$34<$L15),$M15,1E+99) -> 1e+99
J16: HMA3000-6000 | K16: 3000 | L16: 6000 | M16: =L16-K16 -> 3000 | N16: =IF(AND(formula!$K$20>$K16,formula!$K$20<$L16),$M16,1E+99) -> 1e+99 | O16: =IF(AND(formula!$K$34>$K16,formula!$K$34<$L16),$M16,1E+99) -> 1e+99
J17: HMA6000-10000 | K17: 6000 | L17: 10000 | M17: =L17-K17 -> 4000 | N17: =IF(AND(formula!$K$20>$K17,formula!$K$20<$L17),$M17,1E+99) -> 4000 | O17: =IF(AND(formula!$K$34>$K17,formula!$K$34<$L17),$M17,1E+99) -> 4000
J18: HMA10000-15000 | K18: 10000 | L18: 15000 | M18: =L18-K18 -> 5000 | N18: =IF(AND(formula!$K$20>$K18,formula!$K$20<$L18),$M18,1E+99) -> 1e+99 | O18: =IF(AND(formula!$K$34>$K18,formula!$K$34<$L18),$M18,1E+99) -> 1e+99
N20: =MIN(N2:N18) -> 4000 | O20: =MIN(O2:O18) -> 4000
N21: =IF(N20<1E+98,MATCH(N20,N2:N18,0),1) -> 16 | O21: =IF(O20<1E+98,MATCH(O20,O2:O18,0),1) -> 16
